<?xml version="1.0" encoding="utf-8"?>

<robot name="car">
  <link name="base_link">
    <inertial>
      <origin xyz="-2.89659483427445 1.10001092434988E-14 1.03672946451707" rpy="0 0 0" />
      <mass value="17432.032798497" />
      <inertia ixx="9357.94654211181" ixy="-1.26060446501624E-10" ixz="-1547.1262306227" iyy="42349.3870226843" iyz="-1.01196747271312E-11" izz="46064.4886813343" />
    </inertial>
    <visual>
      <origin xyz="0 0 0" rpy="0 0 0" />
      <geometry>
        <mesh filename="package://car/meshes/base_link.STL" />
      </geometry>
      <material name="">
        <color rgba="0.898039215686275 0.917647058823529 0.929411764705882 1" />
      </material>
    </visual>
    <collision>
      <origin xyz="0 0 0" rpy="0 0 0" />
      <geometry>
        <mesh filename="package://car/meshes/base_link.STL" />
      </geometry>
    </collision>
  </link>
  <link name="wheel_lf">
    <inertial>
      <origin xyz="-2.22044604925031E-16 4.44089209850063E-16 0.16" rpy="0 0 0" />
      <mass value="195.872333513578" />
      <inertia ixx="10.0526194504852" ixy="-4.44089209850063E-16" ixz="-1.40195071728621E-14" iyy="10.0526194504852" iyz="1.96135447538109E-14" izz="16.8524046276173" />
    </inertial>
    <visual>
      <origin xyz="0 0 0" rpy="0 0 0" />
      <geometry>
        <mesh filename="package://car/meshes/wheel_lf.STL" />
      </geometry>
      <material name="rubber">
        <color rgba="1 1 1 1" />
      </material>
    </visual>
    <collision>
      <origin xyz="0 0 0" rpy="0 0 0" />
      <geometry>
        <mesh filename="package://car/meshes/wheel_lf.STL" />
      </geometry>
    </collision>
  </link>
  <joint name="joint_lf" type="continuous">
    <origin xyz="-0.886590000000002 0.630000000000016 0.422985466863979" rpy="-1.5707963267949 0.958087741007821 0" />
    <parent link="base_link" />
    <child link="wheel_lf" />
    <axis xyz="0 0 1" />
  </joint>
  <link name="wheel_lr">
    <inertial>
      <origin xyz="-1.77635683940025E-15 -5.55111512312578E-17 0.16" rpy="0 0 0" />
      <mass value="195.872333513578" />
      <inertia ixx="10.0526194504852" ixy="-6.51011529597682E-30" ixz="-2.39496003678538E-14" iyy="10.0526194504852" iyz="1.18124621258017E-31" izz="16.8524046276173" />
    </inertial>
    <visual>
      <origin xyz="0 0 0" rpy="0 0 0" />
      <geometry>
        <mesh filename="package://car/meshes/wheel_lr.STL" />
      </geometry>
      <material name="rubber">
        <color rgba="1 1 1 1" />
      </material>
    </visual>
    <collision>
      <origin xyz="0 0 0" rpy="0 0 0" />
      <geometry>
        <mesh filename="package://car/meshes/wheel_lr.STL" />
      </geometry>
    </collision>
  </link>
  <joint name="joint_lr" type="continuous">
    <origin xyz="-4.11659 0.630000000000004 0.422985466863991" rpy="-1.5707963267949 0 0" />
    <parent link="base_link" />
    <child link="wheel_lr" />
    <axis xyz="0 0 1" />
  </joint>
  <link name="wheel_rf">
    <inertial>
      <origin xyz="-4.4409E-16 4.4409E-16 0.16" rpy="0 0 0" />
      <mass value="195.87" />
      <inertia ixx="10.053" ixy="8.8818E-16" ixz="-2.0266E-14" iyy="10.053" iyz="1.3394E-14" izz="16.852" />
    </inertial>
    <visual>
      <origin xyz="0 0 0" rpy="0 0 0" />
      <geometry>
        <mesh filename="package://car/meshes/wheel_rf.STL" />
      </geometry>
      <material name="rubber">
        <color rgba="1 1 1 1" />
      </material>
    </visual>
    <collision>
      <origin xyz="0 0 0" rpy="0 0 0" />
      <geometry>
        <mesh filename="package://car/meshes/wheel_rf.STL" />
      </geometry>
    </collision>
  </link>
  <joint name="joint_rf" type="continuous">
    <origin xyz="-0.886589999999997 -0.629999999999984 0.422985466863979" rpy="-1.5707963267949 0.578709634858061 3.14159265358979" />
    <parent link="base_link" />
    <child link="wheel_rf" />
    <axis xyz="0 0 -1" />
  </joint>

  <link name="wheel_rr">
    <inertial>
      <origin xyz="0 -5.55111512312578E-17 -0.16" rpy="0 0 0" />
      <mass value="195.872333513578" />
      <inertia ixx="10.0526194504852" ixy="-6.51011529597682E-30" ixz="-2.39496003678538E-14" iyy="10.0526194504852" iyz="1.18124621258017E-31" izz="16.8524046276173" />
    </inertial>
    <visual>
      <origin xyz="0 0 0" rpy="0 0 0" />
      <geometry>
        <mesh filename="package://car/meshes/wheel_rr.STL" />
      </geometry>
      <material name="">
        <color rgba="1 1 1 1" />
      </material>
    </visual>
    <collision>
      <origin xyz="0 0 0" rpy="0 0 0" />
      <geometry>
        <mesh filename="package://car/meshes/wheel_rr.STL" />
      </geometry>
    </collision>
  </link>

  <joint name="joint_rr" type="continuous">
    <origin xyz="-4.11659 -0.629999999999996 0.422985466863991" rpy="-1.5707963267949 0 0" />
    <parent link="base_link" />
    <child link="wheel_rr" />
    <axis xyz="0  0 1" />
  </joint>

  <!-- 激光雷达 -->
  <joint name="velodyne_base_mount_joint" type="fixed">
    <origin xyz="0 0 3" rpy="0 0 0"/>
    <parent link="base_link"/>
    <child link="velodyne_base_link"/>
  </joint>

  <link name="velodyne_base_link">
    <inertial>
      <mass value="0.83"/>
      <origin xyz="0 0 0.03585"/>
      <inertia ixx="0.000908059425" ixy="0" ixz="0" iyy="0.000908059425" iyz="0" izz="0.0011049624"/>
    </inertial>
    <visual>
      <geometry>
        <mesh filename="$(find velodyne_description)/meshes/VLP16_base_1.dae"/>
      </geometry>
    </visual>
    <visual>
      <geometry>
        <mesh filename="$(find velodyne_description)/meshes/VLP16_base_2.dae"/>
      </geometry>
    </visual>
    <collision>
      <origin rpy="0 0 0" xyz="0 0 3"/>
      <geometry>
        <cylinder length="0.0717" radius="0.0516"/>
      </geometry>
    </collision>
  </link>



  <!-- Drive controller -->
  <gazebo>
    <plugin name="skid_steer_drive_controller" filename="libgazebo_ros_skid_steer_drive.so">
      <updateRate>100.0</updateRate>
      <robotNamespace>/</robotNamespace>
      <leftFrontJoint>joint_lf</leftFrontJoint>
      <rightFrontJoint>joint_rf</rightFrontJoint>
      <leftRearJoint>joint_lr</leftRearJoint>
      <rightRearJoint>joint_rr</rightRearJoint>
      <wheelSeparation>4</wheelSeparation>
      <wheelDiameter>1</wheelDiameter>
      <robotBaseFrame>base_link</robotBaseFrame>
      <torque>3000000</torque>
      <commandTopic>cmd_vel</commandTopic>
      <odometryTopic>odom</odometryTopic>
      <odometryFrame>odom</odometryFrame>
      <broadcastTF>true</broadcastTF>
    </plugin>
  </gazebo>
</robot>