<?xml version="1.0" ?>
<!-- =================================================================================== -->
<!-- |    This document was autogenerated by xacro from car.xacro                      | -->
<!-- |    EDITING THIS FILE BY HAND IS NOT RECOMMENDED                                 | -->
<!-- =================================================================================== -->
<robot name="car">
  <!-- <origin xyz="1.5552 0.63 -0.695" rpy="0 0 0" />
<parent link="vehicle_base_link" /> -->
  <material name="tire_mat">
    <color rgba="0 0 0 1"/>
  </material>
  <material name="yellow">
    <color rgba="1 0.4 0 1"/>
  </material>
  <!-- ###################### -->
  <gazebo reference="vehicle_base_link">
    <material>Gazebo/Orange</material>
  </gazebo>
  <gazebo reference="wheel_lf">
    <material>Gazebo/Black</material>
  </gazebo>
  <gazebo reference="wheel_lr">
    <material>Gazebo/Black</material>
  </gazebo>
  <gazebo reference="wheel_rf">
    <material>Gazebo/Black</material>
  </gazebo>
  <gazebo reference="wheel_rr">
    <material>Gazebo/Black</material>
  </gazebo>
  <gazebo reference="plate_l">
    <material>Gazebo/Orange</material>
  </gazebo>
  <gazebo reference="plate_r">
    <material>Gazebo/Orange</material>
  </gazebo>
  <link name="vehicle_base_link">
    <inertial>
      <origin rpy="0 0 0" xyz="-0.446594834274452 1.10140809459871E-14 -0.0812605354829313"/>
      <!-- <mass value="17432.032798497" />
      <inertia ixx="9357.94654211181" ixy="-1.25947873442229E-10" ixz="-1547.1262306227" iyy="42349.3870226843" iyz="-9.50421805128393E-12" izz="46064.4886813343" /> -->
      <!-- <mass value="10000" />
      <inertia ixx="6000" ixy="0" ixz="-1000" iyy="28000" iyz="0" izz="15000" /> -->
      <mass value="10"/>
      <inertia ixx="400" ixy="0" ixz="-0.1" iyy="100" iyz="0" izz="1"/>
    </inertial>
    <visual>
      <origin rpy="0 0 0" xyz="0 0 0"/>
      <geometry>
        <mesh filename="package://car/meshes/vehicle_base_link.STL"/>
      </geometry>
      <material name="Orange">
        <color rgba="1.0 0.33 0.0 1.0"/>
      </material>
    </visual>
    <collision>
      <origin rpy="0 0 0" xyz="0 0 0"/>
      <geometry>
        <mesh filename="package://car/meshes/vehicle_base_link.STL"/>
      </geometry>
    </collision>
  </link>
  <link name="plate_l">
    <inertial>
      <origin rpy="0 0 0" xyz="-4.44089209850063E-16 -2.22044604925031E-16 0.00100000000000067"/>
      <mass value="0.0831265416139861"/>
      <inertia ixx="0.000101857722324338" ixy="-6.70850094225479E-21" ixz="3.74007284466562E-19" iyy="0.000101857722324338" iyz="9.60487555893223E-23" izz="0.000203660026954266"/>
    </inertial>
    <visual>
      <origin rpy="0 0 0" xyz="0 0 0"/>
      <geometry>
        <mesh filename="package://car/meshes/plate_l.STL"/>
      </geometry>
      <material name="Orange">
        <color rgba="1.0 0.33 0.0 1.0"/>
      </material>
    </visual>
    <collision>
      <origin rpy="0 0 0" xyz="0 0 0"/>
      <geometry>
        <mesh filename="package://car/meshes/plate_l.STL"/>
      </geometry>
    </collision>
  </link>
  <joint name="joint_pl" type="fixed">
    <origin rpy="0 0 0" xyz="2.1934 0.95 0.27"/>
    <parent link="vehicle_base_link"/>
    <child link="plate_l"/>
    <axis xyz="0 0 0"/>
  </joint>
  <link name="plate_r">
    <inertial>
      <origin rpy="0 0 0" xyz="-4.44089209850063E-16 1.11022302462516E-16 0.00100000000000039"/>
      <mass value="0.0831265416139861"/>
      <inertia ixx="0.000101857722324338" ixy="3.76876721968964E-21" ixz="3.74111586635625E-19" iyy="0.000101857722324338" iyz="7.8828622518223E-23" izz="0.000203660026954266"/>
    </inertial>
    <visual>
      <origin rpy="0 0 0" xyz="0 0 0"/>
      <geometry>
        <mesh filename="package://car/meshes/plate_r.STL"/>
      </geometry>
      <material name="Orange">
        <color rgba="1.0 0.33 0.0 1.0"/>
      </material>
    </visual>
    <collision>
      <origin rpy="0 0 0" xyz="0 0 0"/>
      <geometry>
        <mesh filename="package://car/meshes/plate_r.STL"/>
      </geometry>
    </collision>
  </link>
  <joint name="joint_pr" type="fixed">
    <origin rpy="0 0 0" xyz="2.1934 -0.95 0.27"/>
    <parent link="vehicle_base_link"/>
    <child link="plate_r"/>
    <axis xyz="0 0 0"/>
  </joint>
  <joint name="left_front_shock" type="prismatic">
    <parent link="vehicle_base_link"/>
    <child link="left_steering_link"/>
    <origin xyz="3.0                    1.4                    -0.42350000000000004"/>
    <axis xyz="0 0 -1"/>
    <limit effort="20" lower="-0.042" upper="0.042" velocity="1000"/>
  </joint>
  <transmission name="left_front_shock_trans">
    <type>transmission_interface/SimpleTransmission</type>
    <joint name="left_front_shock">
      <hardwareInterface>hardware_interface/EffortJointInterface</hardwareInterface>
    </joint>
    <actuator name="left_front_shock_act">
      <!-- This hardwareInterface element exists for compatibility
             with ROS Hydro. -->
      <hardwareInterface>hardware_interface/EffortJointInterface</hardwareInterface>
      <mechanicalReduction>1</mechanicalReduction>
    </actuator>
  </transmission>
  <link name="left_steering_link">
    <inertial>
      <mass value="0.001"/>
      <inertia ixx="0.001" ixy="0" ixz="0" iyy="0.001" iyz="0" izz="0.001"/>
    </inertial>
  </link>
  <joint name="left_steering_joint" type="revolute">
    <parent link="left_steering_link"/>
    <child link="left_front_axle_carrier"/>
    <axis xyz="0 0 1"/>
    <limit effort="0.5649" lower="-0.785398163" upper="0.785398163" velocity="4.553"/>
  </joint>
  <transmission name="left_steering_trans">
    <type>transmission_interface/SimpleTransmission</type>
    <joint name="left_steering_joint">
      <hardwareInterface>hardware_interface/EffortJointInterface</hardwareInterface>
    </joint>
    <actuator name="left_steering_act">
      <!-- This hardwareInterface element exists for compatibility
             with ROS Hydro. -->
      <hardwareInterface>hardware_interface/EffortJointInterface</hardwareInterface>
      <mechanicalReduction>1</mechanicalReduction>
    </actuator>
  </transmission>
  <link name="left_front_axle_carrier">
    <inertial>
      <mass value="0.001"/>
      <inertia ixx="0.001" ixy="0" ixz="0" iyy="0.001" iyz="0" izz="0.001"/>
    </inertial>
  </link>
  <!-- The left and right axles have the same axis so that identical
         rotation values cause the wheels to rotate in the same direction. -->
  <joint name="left_front_axle" type="continuous">
    <parent link="left_front_axle_carrier"/>
    <child link="left_front_wheel"/>
    <origin rpy="1.57079633 0 0" xyz="0 0 0"/>
    <axis xyz="0 0 -1"/>
    <limit effort="10" velocity="244.8696"/>
  </joint>
  <transmission name="left_front_axle_trans">
    <type>transmission_interface/SimpleTransmission</type>
    <joint name="left_front_axle">
      <hardwareInterface>hardware_interface/EffortJointInterface</hardwareInterface>
    </joint>
    <actuator name="left_front_axle_act">
      <!-- This hardwareInterface element exists for compatibility
             with ROS Hydro. -->
      <hardwareInterface>hardware_interface/EffortJointInterface</hardwareInterface>
      <mechanicalReduction>1</mechanicalReduction>
    </actuator>
  </transmission>
  <link name="left_front_wheel">
    <visual>
      <origin xyz="0                      1.3877787807814457e-17                      0"/>
      <geometry>
        <cylinder length="0.3" radius="0.15"/>
      </geometry>
      <material name="tire_mat"/>
    </visual>
    <collision>
      <origin xyz="0                      1.3877787807814457e-17                      0"/>
      <geometry>
        <cylinder length="0.3" radius="0.15"/>
      </geometry>
    </collision>
    <inertial>
      <mass value="0.3"/>
      <inertia ixx="0.004125" ixy="0" ixz="0" iyy="0.004125" iyz="0" izz="0.00375"/>
    </inertial>
  </link>
  <gazebo reference="left_front_wheel">
    <material>Gazebo/Black</material>
  </gazebo>
  <joint name="right_front_shock" type="prismatic">
    <parent link="vehicle_base_link"/>
    <child link="right_steering_link"/>
    <origin xyz="3.0                    -1.4                    -0.42350000000000004"/>
    <axis xyz="0 0 -1"/>
    <limit effort="20" lower="-0.042" upper="0.042" velocity="1000"/>
  </joint>
  <transmission name="right_front_shock_trans">
    <type>transmission_interface/SimpleTransmission</type>
    <joint name="right_front_shock">
      <hardwareInterface>hardware_interface/EffortJointInterface</hardwareInterface>
    </joint>
    <actuator name="right_front_shock_act">
      <!-- This hardwareInterface element exists for compatibility
             with ROS Hydro. -->
      <hardwareInterface>hardware_interface/EffortJointInterface</hardwareInterface>
      <mechanicalReduction>1</mechanicalReduction>
    </actuator>
  </transmission>
  <link name="right_steering_link">
    <inertial>
      <mass value="0.001"/>
      <inertia ixx="0.001" ixy="0" ixz="0" iyy="0.001" iyz="0" izz="0.001"/>
    </inertial>
  </link>
  <joint name="right_steering_joint" type="revolute">
    <parent link="right_steering_link"/>
    <child link="right_front_axle_carrier"/>
    <axis xyz="0 0 1"/>
    <limit effort="0.5649" lower="-0.785398163" upper="0.785398163" velocity="4.553"/>
  </joint>
  <transmission name="right_steering_trans">
    <type>transmission_interface/SimpleTransmission</type>
    <joint name="right_steering_joint">
      <hardwareInterface>hardware_interface/EffortJointInterface</hardwareInterface>
    </joint>
    <actuator name="right_steering_act">
      <!-- This hardwareInterface element exists for compatibility
             with ROS Hydro. -->
      <hardwareInterface>hardware_interface/EffortJointInterface</hardwareInterface>
      <mechanicalReduction>1</mechanicalReduction>
    </actuator>
  </transmission>
  <link name="right_front_axle_carrier">
    <inertial>
      <mass value="0.001"/>
      <inertia ixx="0.001" ixy="0" ixz="0" iyy="0.001" iyz="0" izz="0.001"/>
    </inertial>
  </link>
  <!-- The left and right axles have the same axis so that identical
         rotation values cause the wheels to rotate in the same direction. -->
  <joint name="right_front_axle" type="continuous">
    <parent link="right_front_axle_carrier"/>
    <child link="right_front_wheel"/>
    <origin rpy="1.57079633 0 0" xyz="0 0 0"/>
    <axis xyz="0 0 -1"/>
    <limit effort="10" velocity="244.8696"/>
  </joint>
  <transmission name="right_front_axle_trans">
    <type>transmission_interface/SimpleTransmission</type>
    <joint name="right_front_axle">
      <hardwareInterface>hardware_interface/EffortJointInterface</hardwareInterface>
    </joint>
    <actuator name="right_front_axle_act">
      <!-- This hardwareInterface element exists for compatibility
             with ROS Hydro. -->
      <hardwareInterface>hardware_interface/EffortJointInterface</hardwareInterface>
      <mechanicalReduction>1</mechanicalReduction>
    </actuator>
  </transmission>
  <link name="right_front_wheel">
    <visual>
      <origin xyz="0                      -1.3877787807814457e-17                      0"/>
      <geometry>
        <cylinder length="0.3" radius="0.15"/>
      </geometry>
      <material name="tire_mat"/>
    </visual>
    <collision>
      <origin xyz="0                      -1.3877787807814457e-17                      0"/>
      <geometry>
        <cylinder length="0.3" radius="0.15"/>
      </geometry>
    </collision>
    <inertial>
      <mass value="0.3"/>
      <inertia ixx="0.004125" ixy="0" ixz="0" iyy="0.004125" iyz="0" izz="0.00375"/>
    </inertial>
  </link>
  <gazebo reference="right_front_wheel">
    <material>Gazebo/Black</material>
  </gazebo>
  <joint name="left_rear_shock" type="prismatic">
    <parent link="vehicle_base_link"/>
    <child link="left_rear_axle_carrier"/>
    <origin xyz="-3.0                    1.4                    -0.42350000000000004"/>
    <axis xyz="0 0 -1"/>
    <limit effort="20" lower="-0.042" upper="0.042" velocity="1000"/>
  </joint>
  <transmission name="left_rear_shock_trans">
    <type>transmission_interface/SimpleTransmission</type>
    <joint name="left_rear_shock">
      <hardwareInterface>hardware_interface/EffortJointInterface</hardwareInterface>
    </joint>
    <actuator name="left_rear_shock_act">
      <!-- This hardwareInterface element exists for compatibility
             with ROS Hydro. -->
      <hardwareInterface>hardware_interface/EffortJointInterface</hardwareInterface>
      <mechanicalReduction>1</mechanicalReduction>
    </actuator>
  </transmission>
  <link name="left_rear_axle_carrier">
    <inertial>
      <mass value="0.001"/>
      <inertia ixx="0.001" ixy="0" ixz="0" iyy="0.001" iyz="0" izz="0.001"/>
    </inertial>
  </link>
  <!-- The left and right axles have the same axis so that identical
         rotation values cause the wheels to rotate in the same direction. -->
  <joint name="left_rear_axle" type="continuous">
    <parent link="left_rear_axle_carrier"/>
    <child link="left_rear_wheel"/>
    <origin rpy="1.57079633 0 0" xyz="0 0 0"/>
    <axis xyz="0 0 -1"/>
    <limit effort="10" velocity="244.8696"/>
  </joint>
  <transmission name="left_rear_axle_trans">
    <type>transmission_interface/SimpleTransmission</type>
    <joint name="left_rear_axle">
      <hardwareInterface>hardware_interface/EffortJointInterface</hardwareInterface>
    </joint>
    <actuator name="left_rear_axle_act">
      <!-- This hardwareInterface element exists for compatibility
             with ROS Hydro. -->
      <hardwareInterface>hardware_interface/EffortJointInterface</hardwareInterface>
      <mechanicalReduction>1</mechanicalReduction>
    </actuator>
  </transmission>
  <link name="left_rear_wheel">
    <visual>
      <origin xyz="0                      1.3877787807814457e-17                      0"/>
      <geometry>
        <cylinder length="0.3" radius="0.15"/>
      </geometry>
      <material name="tire_mat"/>
    </visual>
    <collision>
      <origin xyz="0                      1.3877787807814457e-17                      0"/>
      <geometry>
        <cylinder length="0.3" radius="0.15"/>
      </geometry>
    </collision>
    <inertial>
      <mass value="0.3"/>
      <inertia ixx="0.004125" ixy="0" ixz="0" iyy="0.004125" iyz="0" izz="0.00375"/>
    </inertial>
  </link>
  <gazebo reference="left_rear_wheel">
    <material>Gazebo/Black</material>
  </gazebo>
  <joint name="right_rear_shock" type="prismatic">
    <parent link="vehicle_base_link"/>
    <child link="right_rear_axle_carrier"/>
    <origin xyz="-3.0                    -1.4                    -0.42350000000000004"/>
    <axis xyz="0 0 -1"/>
    <limit effort="20" lower="-0.042" upper="0.042" velocity="1000"/>
  </joint>
  <transmission name="right_rear_shock_trans">
    <type>transmission_interface/SimpleTransmission</type>
    <joint name="right_rear_shock">
      <hardwareInterface>hardware_interface/EffortJointInterface</hardwareInterface>
    </joint>
    <actuator name="right_rear_shock_act">
      <!-- This hardwareInterface element exists for compatibility
             with ROS Hydro. -->
      <hardwareInterface>hardware_interface/EffortJointInterface</hardwareInterface>
      <mechanicalReduction>1</mechanicalReduction>
    </actuator>
  </transmission>
  <link name="right_rear_axle_carrier">
    <inertial>
      <mass value="0.001"/>
      <inertia ixx="0.001" ixy="0" ixz="0" iyy="0.001" iyz="0" izz="0.001"/>
    </inertial>
  </link>
  <!-- The left and right axles have the same axis so that identical
         rotation values cause the wheels to rotate in the same direction. -->
  <joint name="right_rear_axle" type="continuous">
    <parent link="right_rear_axle_carrier"/>
    <child link="right_rear_wheel"/>
    <origin rpy="1.57079633 0 0" xyz="0 0 0"/>
    <axis xyz="0 0 -1"/>
    <limit effort="10" velocity="244.8696"/>
  </joint>
  <transmission name="right_rear_axle_trans">
    <type>transmission_interface/SimpleTransmission</type>
    <joint name="right_rear_axle">
      <hardwareInterface>hardware_interface/EffortJointInterface</hardwareInterface>
    </joint>
    <actuator name="right_rear_axle_act">
      <!-- This hardwareInterface element exists for compatibility
             with ROS Hydro. -->
      <hardwareInterface>hardware_interface/EffortJointInterface</hardwareInterface>
      <mechanicalReduction>1</mechanicalReduction>
    </actuator>
  </transmission>
  <link name="right_rear_wheel">
    <visual>
      <origin xyz="0                      -1.3877787807814457e-17                      0"/>
      <geometry>
        <cylinder length="0.3" radius="0.15"/>
      </geometry>
      <material name="tire_mat"/>
    </visual>
    <collision>
      <origin xyz="0                      -1.3877787807814457e-17                      0"/>
      <geometry>
        <cylinder length="0.3" radius="0.15"/>
      </geometry>
    </collision>
    <inertial>
      <mass value="0.3"/>
      <inertia ixx="0.004125" ixy="0" ixz="0" iyy="0.004125" iyz="0" izz="0.00375"/>
    </inertial>
  </link>
  <gazebo reference="right_rear_wheel">
    <material>Gazebo/Black</material>
  </gazebo>
  <joint name="velodyne_left_base_mount_joint" type="fixed">
    <origin rpy="0 0 0" xyz="0 0 0.002"/>
    <parent link="plate_l"/>
    <child link="velodyne_left_base_link"/>
  </joint>
  <link name="velodyne_left_base_link">
    <inertial>
      <mass value="0.83"/>
      <origin xyz="0 0 0.03585"/>
      <inertia ixx="0.000908059425" ixy="0" ixz="0" iyy="0.000908059425" iyz="0" izz="0.0011049624"/>
    </inertial>
    <visual>
      <geometry>
        <mesh filename="package://car/meshes/VLP16_base_1.dae"/>
      </geometry>
    </visual>
    <visual>
      <geometry>
        <mesh filename="package://car/meshes/VLP16_base_2.dae"/>
      </geometry>
    </visual>
    <collision>
      <origin rpy="0 0 0" xyz="0 0 0.03585"/>
      <geometry>
        <!-- <cylinder radius="0.0516" length="0.0717"/> -->
        <cylinder length="0.0717" radius="0.0516"/>
      </geometry>
    </collision>
  </link>
  <joint name="velodyne_left_base_scan_joint" type="fixed">
    <origin rpy="0 0 0" xyz="0 0 0.0377"/>
    <parent link="velodyne_left_base_link"/>
    <child link="velodyne_left"/>
  </joint>
  <link name="velodyne_left">
    <inertial>
      <mass value="0.01"/>
      <origin xyz="0 0 0"/>
      <inertia ixx="1e-7" ixy="0" ixz="0" iyy="1e-7" iyz="0" izz="1e-7"/>
    </inertial>
    <visual>
      <origin xyz="0 0 -0.0377"/>
      <geometry>
        <mesh filename="package://car/meshes/VLP16_scan.dae"/>
      </geometry>
    </visual>
  </link>
  <!-- Gazebo requires the velodyne_gazebo_plugins package -->
  <gazebo reference="velodyne_left">
    <sensor name="velodyne_left-VLP16" type="ray">
      <pose>0 0 0 0 0 0</pose>
      <visualize>false</visualize>
      <update_rate>10</update_rate>
      <ray>
        <scan>
          <horizontal>
            <samples>440</samples>
            <resolution>1</resolution>
            <min_angle>-3.141592653589793</min_angle>
            <max_angle>3.141592653589793</max_angle>
          </horizontal>
          <vertical>
            <samples>16</samples>
            <resolution>1</resolution>
            <min_angle>-0.2617993877991494</min_angle>
            <max_angle> 0.2617993877991494</max_angle>
          </vertical>
        </scan>
        <range>
          <min>0.07</min>
          <max>131.0</max>
          <resolution>0.001</resolution>
        </range>
        <noise>
          <type>gaussian</type>
          <mean>0.0</mean>
          <stddev>0.0</stddev>
        </noise>
      </ray>
      <plugin filename="libgazebo_ros_velodyne_laser.so" name="gazebo_ros_laser_controller">
        <topicName>/velodyne_left</topicName>
        <frameName>velodyne_left</frameName>
        <organize_cloud>False</organize_cloud>
        <min_range>0.9</min_range>
        <max_range>130.0</max_range>
        <gaussianNoise>0.008</gaussianNoise>
      </plugin>
    </sensor>
  </gazebo>
  <joint name="velodyne_right_base_mount_joint" type="fixed">
    <origin rpy="0 0 0" xyz="0 0 0.002"/>
    <parent link="plate_r"/>
    <child link="velodyne_right_base_link"/>
  </joint>
  <link name="velodyne_right_base_link">
    <inertial>
      <mass value="0.83"/>
      <origin xyz="0 0 0.03585"/>
      <inertia ixx="0.000908059425" ixy="0" ixz="0" iyy="0.000908059425" iyz="0" izz="0.0011049624"/>
    </inertial>
    <visual>
      <geometry>
        <mesh filename="package://car/meshes/VLP16_base_1.dae"/>
      </geometry>
    </visual>
    <visual>
      <geometry>
        <mesh filename="package://car/meshes/VLP16_base_2.dae"/>
      </geometry>
    </visual>
    <collision>
      <origin rpy="0 0 0" xyz="0 0 0.03585"/>
      <geometry>
        <!-- <cylinder radius="0.0516" length="0.0717"/> -->
        <cylinder length="0.0717" radius="0.0516"/>
      </geometry>
    </collision>
  </link>
  <joint name="velodyne_right_base_scan_joint" type="fixed">
    <origin rpy="0 0 0" xyz="0 0 0.0377"/>
    <parent link="velodyne_right_base_link"/>
    <child link="velodyne_right"/>
  </joint>
  <link name="velodyne_right">
    <inertial>
      <mass value="0.01"/>
      <origin xyz="0 0 0"/>
      <inertia ixx="1e-7" ixy="0" ixz="0" iyy="1e-7" iyz="0" izz="1e-7"/>
    </inertial>
    <visual>
      <origin xyz="0 0 -0.0377"/>
      <geometry>
        <mesh filename="package://car/meshes/VLP16_scan.dae"/>
      </geometry>
    </visual>
  </link>
  <!-- Gazebo requires the velodyne_gazebo_plugins package -->
  <gazebo reference="velodyne_right">
    <sensor name="velodyne_right-VLP16" type="ray">
      <pose>0 0 0 0 0 0</pose>
      <visualize>false</visualize>
      <update_rate>10</update_rate>
      <ray>
        <scan>
          <horizontal>
            <samples>440</samples>
            <resolution>1</resolution>
            <min_angle>-3.141592653589793</min_angle>
            <max_angle>3.141592653589793</max_angle>
          </horizontal>
          <vertical>
            <samples>16</samples>
            <resolution>1</resolution>
            <min_angle>-0.2617993877991494</min_angle>
            <max_angle> 0.2617993877991494</max_angle>
          </vertical>
        </scan>
        <range>
          <min>0.07</min>
          <max>131.0</max>
          <resolution>0.001</resolution>
        </range>
        <noise>
          <type>gaussian</type>
          <mean>0.0</mean>
          <stddev>0.0</stddev>
        </noise>
      </ray>
      <plugin filename="libgazebo_ros_velodyne_laser.so" name="gazebo_ros_laser_controller">
        <topicName>/velodyne_right</topicName>
        <frameName>velodyne_right</frameName>
        <organize_cloud>False</organize_cloud>
        <min_range>0.9</min_range>
        <max_range>130.0</max_range>
        <gaussianNoise>0.008</gaussianNoise>
      </plugin>
    </sensor>
  </gazebo>
  <joint name="velodyne_top_base_mount_joint" type="fixed">
    <origin rpy="0 0 0" xyz="0 0 0.695"/>
    <parent link="vehicle_base_link"/>
    <child link="velodyne_top_base_link"/>
  </joint>
  <link name="velodyne_top_base_link">
    <inertial>
      <mass value="1.0"/>
      <origin xyz="0 0 0.07212"/>
      <inertia ixx="0.002188947025" ixy="0" ixz="0" iyy="0.002188947025" iyz="0" izz="0.00091036445"/>
    </inertial>
    <visual>
      <geometry>
        <mesh filename="package://car/meshes/HDL32E_base.dae"/>
      </geometry>
    </visual>
    <collision>
      <origin rpy="0 0 0" xyz="0 0 0.07212"/>
      <geometry>
        <cylinder length="0.14424" radius="0.04267"/>
      </geometry>
    </collision>
  </link>
  <joint name="velodyne_top_base_scan_joint" type="fixed">
    <origin rpy="0 0 0" xyz="0 0 0.09081"/>
    <parent link="velodyne_top_base_link"/>
    <child link="velodyne_top"/>
  </joint>
  <link name="velodyne_top">
    <inertial>
      <mass value="0.01"/>
      <origin xyz="0 0 0"/>
      <inertia ixx="1e-7" ixy="0" ixz="0" iyy="1e-7" iyz="0" izz="1e-7"/>
    </inertial>
    <visual>
      <origin rpy="0 0 0" xyz="0 0 -0.09081"/>
      <geometry>
        <mesh filename="package://car/meshes/HDL32E_scan.dae"/>
      </geometry>
    </visual>
  </link>
  <!-- Gazebo requires the velodyne_gazebo_plugins package -->
  <gazebo reference="velodyne_top">
    <sensor name="velodyne_top-HDL32E" type="ray">
      <pose>0 0 0 0 0 0</pose>
      <visualize>false</visualize>
      <update_rate>10</update_rate>
      <ray>
        <scan>
          <horizontal>
            <samples>220</samples>
            <resolution>1</resolution>
            <min_angle>-3.141592653589793</min_angle>
            <max_angle>3.141592653589793</max_angle>
          </horizontal>
          <vertical>
            <samples>32</samples>
            <resolution>1</resolution>
            <min_angle>-0.5352924815866609</min_angle>
            <max_angle> 0.18622663118779495</max_angle>
          </vertical>
        </scan>
        <range>
          <min>0.3</min>
          <max>131.0</max>
          <resolution>0.001</resolution>
        </range>
        <noise>
          <type>gaussian</type>
          <mean>0.0</mean>
          <stddev>0.0</stddev>
        </noise>
      </ray>
      <plugin filename="libgazebo_ros_velodyne_laser.so" name="gazebo_ros_laser_controller">
        <topicName>/velodyne_top</topicName>
        <frameName>velodyne_top</frameName>
        <organize_cloud>False</organize_cloud>
        <min_range>0.9</min_range>
        <max_range>130.0</max_range>
        <gaussianNoise>0.008</gaussianNoise>
      </plugin>
    </sensor>
  </gazebo>
  <!-- Drive controller -->
  <gazebo>
    <plugin filename="libgazebo_ros_control.so" name="gazebo_ros_control">
      <legacyModeNS>true</legacyModeNS>
      <robotSimType>gazebo_ros_control/DefaultRobotHWSim</robotSimType>
      <robotNamespace>/car</robotNamespace>
    </plugin>
  </gazebo>
</robot>

